<mujoco model="base">
  <compiler angle="radian" meshdir="meshes/" autolimits="true"/>
  <option impratio="20" density="1.2" viscosity="2e-05" cone="elliptic"/>
  <size njmax="5000" nconmax="5000"/>
  <visual>
    <map znear="0.001"/>
  </visual>
  <default/>
  <asset>
    <texture type="skybox" builtin="gradient" rgb1="0.9 0.9 1" rgb2="0.2 0.3 0.4" width="256" height="1536"/>
    <texture type="2d" name="texplane" file="/home/soroushn/code/robosuite-dev/robosuite/models/assets/arenas/../textures/light-gray-floor-tile.png"/>
    <texture type="cube" name="tex-ceramic" file="/home/soroushn/code/robosuite-dev/robosuite/models/assets/arenas/../textures/ceramic.png"/>
    <texture type="cube" name="tex-steel-brushed" file="/home/soroushn/code/robosuite-dev/robosuite/models/assets/arenas/../textures/steel-brushed.png"/>
    <texture type="2d" name="tex-light-gray-plaster" file="/home/soroushn/code/robosuite-dev/robosuite/models/assets/arenas/../textures/light-gray-plaster.png"/>
    <texture type="cube" name="textable" builtin="flat" rgb1="0.5 0.5 0.5" width="512" height="3072"/>
    <texture type="cube" name="stand_brass" file="/home/soroushn/code/robosuite-dev/robosuite/models/assets/textures/brass-ambra.png"/>
    <texture type="cube" name="frame_brass" file="/home/soroushn/code/robosuite-dev/robosuite/models/assets/textures/brass-ambra.png"/>
    <texture type="cube" name="frame_ceramic" file="/home/soroushn/code/robosuite-dev/robosuite/models/assets/textures/ceramic.png"/>
    <texture type="cube" name="frame_steel" file="/home/soroushn/code/robosuite-dev/robosuite/models/assets/textures/steel-scratched.png"/>
    <texture type="cube" name="tool_hole1_steel" file="/home/soroushn/code/robosuite-dev/robosuite/models/assets/textures/steel-scratched.png"/>
    <texture type="cube" name="tool_hole2_steel" file="/home/soroushn/code/robosuite-dev/robosuite/models/assets/textures/steel-scratched.png"/>
    <texture type="cube" name="tool_handle_steel" file="/home/soroushn/code/robosuite-dev/robosuite/models/assets/textures/steel-scratched.png"/>
    <material name="floorplane" texture="texplane" texuniform="true" texrepeat="2 2" specular="0" shininess="0" reflectance="0.01"/>
    <material name="table_ceramic" texture="tex-ceramic" specular="0.2" shininess="0"/>
    <material name="table_legs_metal" texture="tex-steel-brushed" shininess="0.8" reflectance="0.8"/>
    <material name="walls_mat" texture="tex-light-gray-plaster" texuniform="true" texrepeat="3 3" specular="0.1" shininess="0.1"/>
    <material name="table_mat" texture="textable"/>
    <material name="robot0_Face636_001" shininess="0.45" rgba="0.901961 0.921569 0.929412 1"/>
    <material name="robot0_Part__Feature017_001" shininess="0.45"/>
    <material name="robot0_Part__Feature018_001" shininess="0.45"/>
    <material name="robot0_Part__Feature019_001" shininess="0.45"/>
    <material name="robot0_Part__Feature022_001" shininess="0.45" rgba="0.901961 0.921569 0.929412 1"/>
    <material name="robot0_Part__Feature023_001" shininess="0.45" rgba="0.25098 0.25098 0.25098 1"/>
    <material name="robot0_Shell001_001" shininess="0.45" rgba="0.25098 0.25098 0.25098 1"/>
    <material name="robot0_Shell002_001" shininess="0.45" rgba="0.901961 0.921569 0.929412 1"/>
    <material name="robot0_Shell003_001" shininess="0.45" rgba="0.901961 0.921569 0.929412 1"/>
    <material name="robot0_Shell009_001" shininess="0.45" rgba="0.25098 0.25098 0.25098 1"/>
    <material name="robot0_Shell010_001" shininess="0.45" rgba="0.901961 0.921569 0.929412 1"/>
    <material name="robot0_Shell_001" shininess="0.45" rgba="0.25098 0.25098 0.25098 1"/>
    <material name="robot0_Part__Feature_001" shininess="0.45"/>
    <material name="robot0_Part__Feature024" shininess="0.45"/>
    <material name="robot0_Part__Feature001_010_001_002" shininess="0.45"/>
    <material name="robot0_Part__Feature002_007_001_002" shininess="0.45"/>
    <material name="robot0_Part__Feature003_004_001_002" shininess="0.45"/>
    <material name="robot0_Part__Feature_001_001_001_002" shininess="0.45" rgba="0.25098 0.25098 0.25098 1"/>
    <material name="robot0_Part__Feature001_001_003_001" shininess="0.45"/>
    <material name="robot0_Part__Feature002_001_003_001" shininess="0.45" rgba="0.25098 0.25098 0.25098 1"/>
    <material name="robot0_Part__Feature003_001_003_001" shininess="0.45"/>
    <material name="robot0_Part__Feature_002_003_001" shininess="0.45"/>
    <material name="robot0_Part__Feature_002_004_003" shininess="0.45"/>
    <material name="robot0_Shell001_001_001_003" shininess="0.45" rgba="0.25 0.25 0.25 1"/>
    <material name="robot0_Shell_001_001_003" shininess="0.45"/>
    <material name="robot0_Face064_002_001_002_001" shininess="0.45" rgba="1 0 0 1"/>
    <material name="robot0_Face065_002_001_002_001" shininess="0.45" rgba="0 1 0 1"/>
    <material name="robot0_Face374_002_001_002_001" shininess="0.45"/>
    <material name="robot0_Face539_002_001_002_001" shininess="0.45" rgba="0.25098 0.25098 0.25098 1"/>
    <material name="robot0_Part__Feature001_009_001_002_001" shininess="0.45" rgba="0.25098 0.25098 0.25098 1"/>
    <material name="robot0_Part__Feature002_006_001_002_001" shininess="0.45" rgba="0.25098 0.25098 0.25098 1"/>
    <material name="robot0_Shell002_002_001_002_001" shininess="0.45"/>
    <material name="robot0_Shell003_002_001_002_001" shininess="0.45"/>
    <material name="robot0_Shell004_001_001_002_001" shininess="0.45"/>
    <material name="robot0_Shell005_001_001_002_001" shininess="0.45"/>
    <material name="robot0_Shell006_003_002_001" shininess="0.45" rgba="0.901961 0.921569 0.929412 1"/>
    <material name="robot0_Shell007_002_002_001" shininess="0.45" rgba="0.25 0.25 0.25 1"/>
    <material name="robot0_Shell011_002_002_001" shininess="0.45"/>
    <material name="robot0_Shell012_002_002_001" shininess="0.45"/>
    <material name="robot0_Shell_003_001_002_001" shininess="0.45" rgba="0.25098 0.25098 0.25098 1"/>
    <material name="robot0_Union001_001_001_002_001" shininess="0.45" rgba="0.039216 0.541176 0.780392 1"/>
    <material name="robot0_Union_001_001_002_001" shininess="0.45" rgba="0.039216 0.541176 0.780392 1"/>
    <material name="robot0_Part__Mirroring001_004_002" shininess="0.45" rgba="0.25098 0.25098 0.25098 1"/>
    <material name="robot0_Part__Mirroring002_004_001" shininess="0.45" rgba="0.25098 0.25098 0.25098 1"/>
    <material name="robot0_Part__Mirroring003_004_001" shininess="0.45" rgba="0.25098 0.25098 0.25098 1"/>
    <material name="robot0_Part__Mirroring004_004_002" shininess="0.45"/>
    <material name="robot0_Part__Mirroring005_004_001" shininess="0.45" rgba="0.25098 0.25098 0.25098 1"/>
    <material name="robot0_Part__Mirroring006_004_001" shininess="0.45" rgba="0.25098 0.25098 0.25098 1"/>
    <material name="robot0_Part__Mirroring007_004_001" shininess="0.45" rgba="0.25098 0.25098 0.25098 1"/>
    <material name="robot0_Part__Mirroring_004_001" shininess="0.45" rgba="0.898039 0.917647 0.929412 1"/>
    <material name="stand_brass_mat" texture="stand_brass" texrepeat="3 3" specular="0.4" shininess="0.1"/>
    <material name="frame_brass_mat" texture="frame_brass" texrepeat="3 3" specular="0.4" shininess="0.1"/>
    <material name="frame_ceramic_mat" texture="frame_ceramic" texrepeat="3 3" specular="0.4" shininess="0.1"/>
    <material name="frame_steel_mat" texture="frame_steel" texrepeat="3 3" specular="0.4" shininess="0.1"/>
    <material name="tool_hole1_steel_mat" texture="tool_hole1_steel" texrepeat="3 3" specular="0.4" shininess="0.1"/>
    <material name="tool_hole2_steel_mat" texture="tool_hole2_steel" texrepeat="3 3" specular="0.4" shininess="0.1"/>
    <material name="tool_handle_steel_mat" texture="tool_handle_steel" texrepeat="3 3" specular="0.4" shininess="0.1"/>
    <mesh name="robot0_link0" file="/home/soroushn/code/robosuite-dev/robosuite/models/assets/robots/panda/meshes/link0.stl"/>
    <mesh name="robot0_link1" file="/home/soroushn/code/robosuite-dev/robosuite/models/assets/robots/panda/meshes/link1.stl"/>
    <mesh name="robot0_link2" file="/home/soroushn/code/robosuite-dev/robosuite/models/assets/robots/panda/meshes/link2.stl"/>
    <mesh name="robot0_link3" file="/home/soroushn/code/robosuite-dev/robosuite/models/assets/robots/panda/meshes/link3.stl"/>
    <mesh name="robot0_link4" file="/home/soroushn/code/robosuite-dev/robosuite/models/assets/robots/panda/meshes/link4.stl"/>
    <mesh name="robot0_link5" file="/home/soroushn/code/robosuite-dev/robosuite/models/assets/robots/panda/meshes/link5.stl"/>
    <mesh name="robot0_link6" file="/home/soroushn/code/robosuite-dev/robosuite/models/assets/robots/panda/meshes/link6.stl"/>
    <mesh name="robot0_link7" file="/home/soroushn/code/robosuite-dev/robosuite/models/assets/robots/panda/meshes/link7.stl"/>
    <mesh name="robot0_link0_vis_0" file="/home/soroushn/code/robosuite-dev/robosuite/models/assets/robots/panda/obj_meshes/link0_vis/link0_vis_0.obj"/>
    <mesh name="robot0_link0_vis_1" file="/home/soroushn/code/robosuite-dev/robosuite/models/assets/robots/panda/obj_meshes/link0_vis/link0_vis_1.obj"/>
    <mesh name="robot0_link0_vis_2" file="/home/soroushn/code/robosuite-dev/robosuite/models/assets/robots/panda/obj_meshes/link0_vis/link0_vis_2.obj"/>
    <mesh name="robot0_link0_vis_3" file="/home/soroushn/code/robosuite-dev/robosuite/models/assets/robots/panda/obj_meshes/link0_vis/link0_vis_3.obj"/>
    <mesh name="robot0_link0_vis_4" file="/home/soroushn/code/robosuite-dev/robosuite/models/assets/robots/panda/obj_meshes/link0_vis/link0_vis_4.obj"/>
    <mesh name="robot0_link0_vis_5" file="/home/soroushn/code/robosuite-dev/robosuite/models/assets/robots/panda/obj_meshes/link0_vis/link0_vis_5.obj"/>
    <mesh name="robot0_link0_vis_6" file="/home/soroushn/code/robosuite-dev/robosuite/models/assets/robots/panda/obj_meshes/link0_vis/link0_vis_6.obj"/>
    <mesh name="robot0_link0_vis_7" file="/home/soroushn/code/robosuite-dev/robosuite/models/assets/robots/panda/obj_meshes/link0_vis/link0_vis_7.obj"/>
    <mesh name="robot0_link0_vis_8" file="/home/soroushn/code/robosuite-dev/robosuite/models/assets/robots/panda/obj_meshes/link0_vis/link0_vis_8.obj"/>
    <mesh name="robot0_link0_vis_9" file="/home/soroushn/code/robosuite-dev/robosuite/models/assets/robots/panda/obj_meshes/link0_vis/link0_vis_9.obj"/>
    <mesh name="robot0_link0_vis_10" file="/home/soroushn/code/robosuite-dev/robosuite/models/assets/robots/panda/obj_meshes/link0_vis/link0_vis_10.obj"/>
    <mesh name="robot0_link0_vis_11" file="/home/soroushn/code/robosuite-dev/robosuite/models/assets/robots/panda/obj_meshes/link0_vis/link0_vis_11.obj"/>
    <mesh name="robot0_link1_vis" file="/home/soroushn/code/robosuite-dev/robosuite/models/assets/robots/panda/obj_meshes/link1_vis/link1_vis.obj"/>
    <mesh name="robot0_link2_vis" file="/home/soroushn/code/robosuite-dev/robosuite/models/assets/robots/panda/obj_meshes/link2_vis/link2_vis.obj"/>
    <mesh name="robot0_link3_vis_0" file="/home/soroushn/code/robosuite-dev/robosuite/models/assets/robots/panda/obj_meshes/link3_vis/link3_vis_0.obj"/>
    <mesh name="robot0_link3_vis_1" file="/home/soroushn/code/robosuite-dev/robosuite/models/assets/robots/panda/obj_meshes/link3_vis/link3_vis_1.obj"/>
    <mesh name="robot0_link3_vis_2" file="/home/soroushn/code/robosuite-dev/robosuite/models/assets/robots/panda/obj_meshes/link3_vis/link3_vis_2.obj"/>
    <mesh name="robot0_link3_vis_3" file="/home/soroushn/code/robosuite-dev/robosuite/models/assets/robots/panda/obj_meshes/link3_vis/link3_vis_3.obj"/>
    <mesh name="robot0_link4_vis_0" file="/home/soroushn/code/robosuite-dev/robosuite/models/assets/robots/panda/obj_meshes/link4_vis/link4_vis_0.obj"/>
    <mesh name="robot0_link4_vis_1" file="/home/soroushn/code/robosuite-dev/robosuite/models/assets/robots/panda/obj_meshes/link4_vis/link4_vis_1.obj"/>
    <mesh name="robot0_link4_vis_2" file="/home/soroushn/code/robosuite-dev/robosuite/models/assets/robots/panda/obj_meshes/link4_vis/link4_vis_2.obj"/>
    <mesh name="robot0_link4_vis_3" file="/home/soroushn/code/robosuite-dev/robosuite/models/assets/robots/panda/obj_meshes/link4_vis/link4_vis_3.obj"/>
    <mesh name="robot0_link5_vis_0" file="/home/soroushn/code/robosuite-dev/robosuite/models/assets/robots/panda/obj_meshes/link5_vis/link5_vis_0.obj"/>
    <mesh name="robot0_link5_vis_1" file="/home/soroushn/code/robosuite-dev/robosuite/models/assets/robots/panda/obj_meshes/link5_vis/link5_vis_1.obj"/>
    <mesh name="robot0_link5_vis_2" file="/home/soroushn/code/robosuite-dev/robosuite/models/assets/robots/panda/obj_meshes/link5_vis/link5_vis_2.obj"/>
    <mesh name="robot0_link6_vis_0" file="/home/soroushn/code/robosuite-dev/robosuite/models/assets/robots/panda/obj_meshes/link6_vis/link6_vis_0.obj"/>
    <mesh name="robot0_link6_vis_1" file="/home/soroushn/code/robosuite-dev/robosuite/models/assets/robots/panda/obj_meshes/link6_vis/link6_vis_1.obj"/>
    <mesh name="robot0_link6_vis_2" file="/home/soroushn/code/robosuite-dev/robosuite/models/assets/robots/panda/obj_meshes/link6_vis/link6_vis_2.obj"/>
    <mesh name="robot0_link6_vis_3" file="/home/soroushn/code/robosuite-dev/robosuite/models/assets/robots/panda/obj_meshes/link6_vis/link6_vis_3.obj"/>
    <mesh name="robot0_link6_vis_4" file="/home/soroushn/code/robosuite-dev/robosuite/models/assets/robots/panda/obj_meshes/link6_vis/link6_vis_4.obj"/>
    <mesh name="robot0_link6_vis_5" file="/home/soroushn/code/robosuite-dev/robosuite/models/assets/robots/panda/obj_meshes/link6_vis/link6_vis_5.obj"/>
    <mesh name="robot0_link6_vis_6" file="/home/soroushn/code/robosuite-dev/robosuite/models/assets/robots/panda/obj_meshes/link6_vis/link6_vis_6.obj"/>
    <mesh name="robot0_link6_vis_7" file="/home/soroushn/code/robosuite-dev/robosuite/models/assets/robots/panda/obj_meshes/link6_vis/link6_vis_7.obj"/>
    <mesh name="robot0_link6_vis_8" file="/home/soroushn/code/robosuite-dev/robosuite/models/assets/robots/panda/obj_meshes/link6_vis/link6_vis_8.obj"/>
    <mesh name="robot0_link6_vis_9" file="/home/soroushn/code/robosuite-dev/robosuite/models/assets/robots/panda/obj_meshes/link6_vis/link6_vis_9.obj"/>
    <mesh name="robot0_link6_vis_10" file="/home/soroushn/code/robosuite-dev/robosuite/models/assets/robots/panda/obj_meshes/link6_vis/link6_vis_10.obj"/>
    <mesh name="robot0_link6_vis_11" file="/home/soroushn/code/robosuite-dev/robosuite/models/assets/robots/panda/obj_meshes/link6_vis/link6_vis_11.obj"/>
    <mesh name="robot0_link6_vis_12" file="/home/soroushn/code/robosuite-dev/robosuite/models/assets/robots/panda/obj_meshes/link6_vis/link6_vis_12.obj"/>
    <mesh name="robot0_link6_vis_13" file="/home/soroushn/code/robosuite-dev/robosuite/models/assets/robots/panda/obj_meshes/link6_vis/link6_vis_13.obj"/>
    <mesh name="robot0_link6_vis_14" file="/home/soroushn/code/robosuite-dev/robosuite/models/assets/robots/panda/obj_meshes/link6_vis/link6_vis_14.obj"/>
    <mesh name="robot0_link6_vis_15" file="/home/soroushn/code/robosuite-dev/robosuite/models/assets/robots/panda/obj_meshes/link6_vis/link6_vis_15.obj"/>
    <mesh name="robot0_link6_vis_16" file="/home/soroushn/code/robosuite-dev/robosuite/models/assets/robots/panda/obj_meshes/link6_vis/link6_vis_16.obj"/>
    <mesh name="robot0_link7_vis_0" file="/home/soroushn/code/robosuite-dev/robosuite/models/assets/robots/panda/obj_meshes/link7_vis/link7_vis_0.obj"/>
    <mesh name="robot0_link7_vis_1" file="/home/soroushn/code/robosuite-dev/robosuite/models/assets/robots/panda/obj_meshes/link7_vis/link7_vis_1.obj"/>
    <mesh name="robot0_link7_vis_2" file="/home/soroushn/code/robosuite-dev/robosuite/models/assets/robots/panda/obj_meshes/link7_vis/link7_vis_2.obj"/>
    <mesh name="robot0_link7_vis_3" file="/home/soroushn/code/robosuite-dev/robosuite/models/assets/robots/panda/obj_meshes/link7_vis/link7_vis_3.obj"/>
    <mesh name="robot0_link7_vis_4" file="/home/soroushn/code/robosuite-dev/robosuite/models/assets/robots/panda/obj_meshes/link7_vis/link7_vis_4.obj"/>
    <mesh name="robot0_link7_vis_5" file="/home/soroushn/code/robosuite-dev/robosuite/models/assets/robots/panda/obj_meshes/link7_vis/link7_vis_5.obj"/>
    <mesh name="robot0_link7_vis_6" file="/home/soroushn/code/robosuite-dev/robosuite/models/assets/robots/panda/obj_meshes/link7_vis/link7_vis_6.obj"/>
    <mesh name="robot0_link7_vis_7" file="/home/soroushn/code/robosuite-dev/robosuite/models/assets/robots/panda/obj_meshes/link7_vis/link7_vis_7.obj"/>
    <mesh name="mount0_pedestal" file="/home/soroushn/code/robosuite-dev/robosuite/models/assets/mounts/meshes/rethink_mount/pedestal.stl"/>
    <mesh name="gripper0_hand" file="/home/soroushn/code/robosuite-dev/robosuite/models/assets/grippers/meshes/panda_gripper/hand.stl"/>
    <mesh name="gripper0_hand_vis" file="/home/soroushn/code/robosuite-dev/robosuite/models/assets/grippers/meshes/panda_gripper/hand_vis.stl"/>
    <mesh name="gripper0_finger" file="/home/soroushn/code/robosuite-dev/robosuite/models/assets/grippers/meshes/panda_gripper/finger.stl"/>
    <mesh name="gripper0_finger_vis" file="/home/soroushn/code/robosuite-dev/robosuite/models/assets/grippers/meshes/panda_gripper/finger_vis.stl"/>
    <mesh name="gripper0_finger_vis2" file="/home/soroushn/code/robosuite-dev/robosuite/models/assets/grippers/meshes/panda_gripper/finger_longer.stl"/>
  </asset>
  <worldbody>
    <geom name="floor" size="3 3 0.125" type="plane" group="1" material="floorplane"/>
    <geom name="wall_leftcorner_visual" size="1.06 1.5 0.01" pos="-1.25 2.25 1.5" quat="0.653281 0.653281 0.270598 0.270598" type="box" contype="0" conaffinity="0" group="1" material="walls_mat"/>
    <geom name="wall_rightcorner_visual" size="1.06 1.5 0.01" pos="-1.25 -2.25 1.5" quat="0.653281 0.653281 -0.270598 -0.270598" type="box" contype="0" conaffinity="0" group="1" material="walls_mat"/>
    <geom name="wall_left_visual" size="1.75 1.5 0.01" pos="1.25 3 1.5" quat="0.707107 0.707107 0 0" type="box" contype="0" conaffinity="0" group="1" material="walls_mat"/>
    <geom name="wall_right_visual" size="1.75 1.5 0.01" pos="1.25 -3 1.5" quat="0.707107 -0.707107 0 0" type="box" contype="0" conaffinity="0" group="1" material="walls_mat"/>
    <geom name="wall_rear_visual" size="1.5 1.5 0.01" pos="-2 0 1.5" quat="0.5 0.5 0.5 0.5" type="box" contype="0" conaffinity="0" group="1" material="walls_mat"/>
    <geom name="wall_front_visual" size="3 1.5 0.01" pos="3 0 1.5" quat="0.5 0.5 -0.5 -0.5" type="box" contype="0" conaffinity="0" group="1" material="walls_mat"/>
    <camera name="frontview" pos="1.6 0 1.45" quat="0.560842 0.430646 0.430646 0.560842"/>
    <camera name="birdview" pos="-0.2 0 3" quat="0.707107 0 0 0.707107"/>
    <camera name="agentview" pos="0.483728 0.250558 1.26394" quat="0.397133 0.278075 0.501661 0.716446"/>
    <camera name="sideview" pos="0.483728 0.250558 1.21394" quat="0.397133 0.278075 0.501661 0.716446"/>
    <light pos="1 1 1.5" dir="-0.19245 -0.19245 -0.96225" directional="true" castshadow="false"/>
    <body name="table" pos="0 0 0.775" gravcomp="0">
      <geom name="table_collision" size="0.4 0.4 0.025" type="box" rgba="0.5 0.5 0 1"/>
      <geom name="table_visual" size="0.4 0.4 0.025" type="box" contype="0" conaffinity="0" group="1" material="table_ceramic"/>
      <geom name="table_leg1_visual" size="0.025 0.3875" pos="0.3 0.3 -0.3875" type="cylinder" contype="0" conaffinity="0" group="1" material="table_legs_metal"/>
      <geom name="table_leg2_visual" size="0.025 0.3875" pos="-0.3 0.3 -0.3875" type="cylinder" contype="0" conaffinity="0" group="1" material="table_legs_metal"/>
      <geom name="table_leg3_visual" size="0.025 0.3875" pos="-0.3 -0.3 -0.3875" type="cylinder" contype="0" conaffinity="0" group="1" material="table_legs_metal"/>
      <geom name="table_leg4_visual" size="0.025 0.3875" pos="0.3 -0.3 -0.3875" type="cylinder" contype="0" conaffinity="0" group="1" material="table_legs_metal"/>
      <site name="table_top" pos="0 0 0.025" size="0.001" rgba="0 0 0 0"/>
    </body>
    <body name="robot0_base" pos="-0.56 0 0.912" gravcomp="0">
      <inertial pos="0 0 0" mass="0" diaginertia="0 0 0"/>
      <camera name="robot0_robotview" pos="1 0 0.4" quat="0.653098 0.271041 0.271041 0.653098"/>
      <body name="robot0_link0" pos="0 0 0" gravcomp="0">
        <inertial pos="0 0 0.05" mass="4" diaginertia="0.4 0.4 0.4"/>
        <geom name="robot0_g0_vis" type="mesh" contype="0" conaffinity="0" group="1" material="robot0_Shell010_001" mesh="robot0_link0_vis_0"/>
        <geom name="robot0_g1_vis" type="mesh" contype="0" conaffinity="0" group="1" material="robot0_Shell009_001" mesh="robot0_link0_vis_1"/>
        <geom name="robot0_g2_vis" type="mesh" contype="0" conaffinity="0" group="1" material="robot0_Shell003_001" mesh="robot0_link0_vis_2"/>
        <geom name="robot0_g3_vis" type="mesh" contype="0" conaffinity="0" group="1" material="robot0_Shell_001" mesh="robot0_link0_vis_3"/>
        <geom name="robot0_g4_vis" type="mesh" contype="0" conaffinity="0" group="1" material="robot0_Shell002_001" mesh="robot0_link0_vis_4"/>
        <geom name="robot0_g5_vis" type="mesh" contype="0" conaffinity="0" group="1" material="robot0_Shell001_001" mesh="robot0_link0_vis_5"/>
        <geom name="robot0_g6_vis" type="mesh" contype="0" conaffinity="0" group="1" material="robot0_Face636_001" mesh="robot0_link0_vis_6"/>
        <geom name="robot0_g7_vis" type="mesh" contype="0" conaffinity="0" group="1" material="robot0_Part__Feature018_001" mesh="robot0_link0_vis_7"/>
        <geom name="robot0_g8_vis" type="mesh" contype="0" conaffinity="0" group="1" material="robot0_Part__Feature019_001" mesh="robot0_link0_vis_8"/>
        <geom name="robot0_g9_vis" type="mesh" contype="0" conaffinity="0" group="1" material="robot0_Part__Feature023_001" mesh="robot0_link0_vis_9"/>
        <geom name="robot0_g10_vis" type="mesh" contype="0" conaffinity="0" group="1" material="robot0_Part__Feature022_001" mesh="robot0_link0_vis_10"/>
        <geom name="robot0_g11_vis" type="mesh" contype="0" conaffinity="0" group="1" material="robot0_Part__Feature017_001" mesh="robot0_link0_vis_11"/>
        <geom name="robot0_link0_collision" type="mesh" rgba="0 0.5 0 1" mesh="robot0_link0"/>
        <body name="robot0_link1" pos="0 0 0.333" gravcomp="0">
          <inertial pos="0 0 -0.07" mass="3" diaginertia="0.3 0.3 0.3"/>
          <joint name="robot0_joint1" pos="0 0 0" axis="0 0 1" range="-2.8973 2.8973" armature="5" damping="0.1" frictionloss="0.1"/>
          <geom name="robot0_g12_vis" type="mesh" contype="0" conaffinity="0" group="1" material="robot0_Part__Feature_001" mesh="robot0_link1_vis"/>
          <geom name="robot0_link1_collision" type="mesh" rgba="0 0.5 0 1" mesh="robot0_link1"/>
          <body name="robot0_link2" pos="0 0 0" quat="0.707107 -0.707107 0 0" gravcomp="0">
            <inertial pos="0 -0.1 0" mass="3" diaginertia="0.3 0.3 0.3"/>
            <joint name="robot0_joint2" pos="0 0 0" axis="0 0 1" range="-1.7628 1.7628" armature="2.5" damping="0.1" frictionloss="0.1"/>
            <geom name="robot0_g13_vis" type="mesh" contype="0" conaffinity="0" group="1" material="robot0_Part__Feature024" mesh="robot0_link2_vis"/>
            <geom name="robot0_link2_collision" type="mesh" rgba="0 0.5 0 1" mesh="robot0_link2"/>
            <body name="robot0_link3" pos="0 -0.316 0" quat="0.707107 0.707107 0 0" gravcomp="0">
              <inertial pos="0.04 0 -0.05" mass="2" diaginertia="0.2 0.2 0.2"/>
              <joint name="robot0_joint3" pos="0 0 0" axis="0 0 1" range="-2.8973 2.8973" armature="1.66667" damping="0.1" frictionloss="0.1"/>
              <geom name="robot0_g14_vis" type="mesh" contype="0" conaffinity="0" group="1" material="robot0_Part__Feature003_004_001_002" mesh="robot0_link3_vis_0"/>
              <geom name="robot0_g15_vis" type="mesh" contype="0" conaffinity="0" group="1" material="robot0_Part__Feature002_007_001_002" mesh="robot0_link3_vis_1"/>
              <geom name="robot0_g16_vis" type="mesh" contype="0" conaffinity="0" group="1" material="robot0_Part__Feature001_010_001_002" mesh="robot0_link3_vis_2"/>
              <geom name="robot0_g17_vis" type="mesh" contype="0" conaffinity="0" group="1" material="robot0_Part__Feature_001_001_001_002" mesh="robot0_link3_vis_3"/>
              <geom name="robot0_link3_collision" type="mesh" rgba="0 0.5 0 1" mesh="robot0_link3"/>
              <body name="robot0_link4" pos="0.0825 0 0" quat="0.707107 0.707107 0 0" gravcomp="0">
                <inertial pos="-0.04 0.05 0" mass="2" diaginertia="0.2 0.2 0.2"/>
                <joint name="robot0_joint4" pos="0 0 0" axis="0 0 1" range="-3.0718 -0.0698" armature="1.25" damping="0.1" frictionloss="0.1"/>
                <geom name="robot0_g18_vis" type="mesh" contype="0" conaffinity="0" group="1" material="robot0_Part__Feature001_001_003_001" mesh="robot0_link4_vis_0"/>
                <geom name="robot0_g19_vis" type="mesh" contype="0" conaffinity="0" group="1" material="robot0_Part__Feature003_001_003_001" mesh="robot0_link4_vis_1"/>
                <geom name="robot0_g20_vis" type="mesh" contype="0" conaffinity="0" group="1" material="robot0_Part__Feature002_001_003_001" mesh="robot0_link4_vis_2"/>
                <geom name="robot0_g21_vis" type="mesh" contype="0" conaffinity="0" group="1" material="robot0_Part__Feature_002_003_001" mesh="robot0_link4_vis_3"/>
                <geom name="robot0_link4_collision" type="mesh" rgba="0 0.5 0 1" mesh="robot0_link4"/>
                <body name="robot0_link5" pos="-0.0825 0.384 0" quat="0.707107 -0.707107 0 0" gravcomp="0">
                  <inertial pos="0 0 -0.15" mass="2" diaginertia="0.2 0.2 0.2"/>
                  <joint name="robot0_joint5" pos="0 0 0" axis="0 0 1" range="-2.8973 2.8973" armature="1" damping="0.1" frictionloss="0.1"/>
                  <geom name="robot0_g22_vis" type="mesh" contype="0" conaffinity="0" group="1" material="robot0_Shell001_001_001_003" mesh="robot0_link5_vis_0"/>
                  <geom name="robot0_g23_vis" type="mesh" contype="0" conaffinity="0" group="1" material="robot0_Shell_001_001_003" mesh="robot0_link5_vis_1"/>
                  <geom name="robot0_g24_vis" type="mesh" contype="0" conaffinity="0" group="1" material="robot0_Part__Feature_002_004_003" mesh="robot0_link5_vis_2"/>
                  <geom name="robot0_link5_collision" type="mesh" rgba="0 0.5 0 1" mesh="robot0_link5"/>
                  <body name="robot0_link6" pos="0 0 0" quat="0.707107 0.707107 0 0" gravcomp="0">
                    <inertial pos="0.06 0 0" mass="1.5" diaginertia="0.1 0.1 0.1"/>
                    <joint name="robot0_joint6" pos="0 0 0" axis="0 0 1" range="-0.0175 3.7525" armature="0.833333" damping="0.01" frictionloss="0.1"/>
                    <geom name="robot0_g25_vis" type="mesh" contype="0" conaffinity="0" group="1" material="robot0_Shell006_003_002_001" mesh="robot0_link6_vis_0"/>
                    <geom name="robot0_g26_vis" type="mesh" contype="0" conaffinity="0" group="1" material="robot0_Shell011_002_002_001" mesh="robot0_link6_vis_1"/>
                    <geom name="robot0_g27_vis" type="mesh" contype="0" conaffinity="0" group="1" material="robot0_Shell007_002_002_001" mesh="robot0_link6_vis_2"/>
                    <geom name="robot0_g28_vis" type="mesh" contype="0" conaffinity="0" group="1" material="robot0_Shell005_001_001_002_001" mesh="robot0_link6_vis_3"/>
                    <geom name="robot0_g29_vis" type="mesh" contype="0" conaffinity="0" group="1" material="robot0_Shell004_001_001_002_001" mesh="robot0_link6_vis_4"/>
                    <geom name="robot0_g30_vis" type="mesh" contype="0" conaffinity="0" group="1" material="robot0_Shell003_002_001_002_001" mesh="robot0_link6_vis_5"/>
                    <geom name="robot0_g31_vis" type="mesh" contype="0" conaffinity="0" group="1" material="robot0_Shell002_002_001_002_001" mesh="robot0_link6_vis_6"/>
                    <geom name="robot0_g32_vis" type="mesh" contype="0" conaffinity="0" group="1" material="robot0_Union001_001_001_002_001" mesh="robot0_link6_vis_7"/>
                    <geom name="robot0_g33_vis" type="mesh" contype="0" conaffinity="0" group="1" material="robot0_Union_001_001_002_001" mesh="robot0_link6_vis_8"/>
                    <geom name="robot0_g34_vis" type="mesh" contype="0" conaffinity="0" group="1" material="robot0_Face539_002_001_002_001" mesh="robot0_link6_vis_9"/>
                    <geom name="robot0_g35_vis" type="mesh" contype="0" conaffinity="0" group="1" material="robot0_Shell_003_001_002_001" mesh="robot0_link6_vis_10"/>
                    <geom name="robot0_g36_vis" type="mesh" contype="0" conaffinity="0" group="1" material="robot0_Face374_002_001_002_001" mesh="robot0_link6_vis_11"/>
                    <geom name="robot0_g37_vis" type="mesh" contype="0" conaffinity="0" group="1" material="robot0_Face065_002_001_002_001" mesh="robot0_link6_vis_12"/>
                    <geom name="robot0_g38_vis" type="mesh" contype="0" conaffinity="0" group="1" material="robot0_Face064_002_001_002_001" mesh="robot0_link6_vis_13"/>
                    <geom name="robot0_g39_vis" type="mesh" contype="0" conaffinity="0" group="1" material="robot0_Part__Feature002_006_001_002_001" mesh="robot0_link6_vis_14"/>
                    <geom name="robot0_g40_vis" type="mesh" contype="0" conaffinity="0" group="1" material="robot0_Part__Feature001_009_001_002_001" mesh="robot0_link6_vis_15"/>
                    <geom name="robot0_g41_vis" type="mesh" contype="0" conaffinity="0" group="1" material="robot0_Shell012_002_002_001" mesh="robot0_link6_vis_16"/>
                    <geom name="robot0_link6_collision" type="mesh" rgba="0 0.5 0 1" mesh="robot0_link6"/>
                    <body name="robot0_link7" pos="0.088 0 0" quat="0.707107 0.707107 0 0" gravcomp="0">
                      <inertial pos="0 0 0.08" mass="0.5" diaginertia="0.05 0.05 0.05"/>
                      <joint name="robot0_joint7" pos="0 0 0" axis="0 0 1" range="-2.8973 2.8973" armature="0.714286" damping="0.01" frictionloss="0.1"/>
                      <geom name="robot0_g42_vis" type="mesh" contype="0" conaffinity="0" group="1" material="robot0_Part__Mirroring004_004_002" mesh="robot0_link7_vis_0"/>
                      <geom name="robot0_g43_vis" type="mesh" contype="0" conaffinity="0" group="1" material="robot0_Part__Mirroring001_004_002" mesh="robot0_link7_vis_1"/>
                      <geom name="robot0_g44_vis" type="mesh" contype="0" conaffinity="0" group="1" material="robot0_Part__Mirroring007_004_001" mesh="robot0_link7_vis_2"/>
                      <geom name="robot0_g45_vis" type="mesh" contype="0" conaffinity="0" group="1" material="robot0_Part__Mirroring006_004_001" mesh="robot0_link7_vis_3"/>
                      <geom name="robot0_g46_vis" type="mesh" contype="0" conaffinity="0" group="1" material="robot0_Part__Mirroring005_004_001" mesh="robot0_link7_vis_4"/>
                      <geom name="robot0_g47_vis" type="mesh" contype="0" conaffinity="0" group="1" material="robot0_Part__Mirroring003_004_001" mesh="robot0_link7_vis_5"/>
                      <geom name="robot0_g48_vis" type="mesh" contype="0" conaffinity="0" group="1" material="robot0_Part__Mirroring002_004_001" mesh="robot0_link7_vis_6"/>
                      <geom name="robot0_g49_vis" type="mesh" contype="0" conaffinity="0" group="1" material="robot0_Part__Mirroring_004_001" mesh="robot0_link7_vis_7"/>
                      <geom name="robot0_link7_collision" type="mesh" rgba="0 0.5 0 1" mesh="robot0_link7"/>
                      <body name="robot0_right_hand" pos="0 0 0.1065" quat="0.923785 0 0 -0.382911" gravcomp="0">
                        <inertial pos="0 0 0" mass="0.5" diaginertia="0.05 0.05 0.05"/>
                        <camera name="robot0_eye_in_hand" pos="0.08 0 0" quat="0 0.707107 0.707107 0" fovy="100"/>
                        <body name="gripper0_right_gripper" pos="0 0 0" quat="0.707107 0 0 -0.707107" gravcomp="0">
                          <inertial pos="0 0 0.17" quat="0.707107 0.707107 0 0" mass="0.3" diaginertia="0.09 0.07 0.05"/>
                          <geom name="gripper0_hand_visual" quat="0.707107 0 0 0.707107" type="mesh" contype="0" conaffinity="0" group="1" rgba="1 1 1 1" mesh="gripper0_hand_vis"/>
                          <geom name="gripper0_hand_collision" quat="0.707107 0 0 0.707107" type="mesh" rgba="0 0 0.5 1" mesh="gripper0_hand"/>
                          <site name="gripper0_ft_frame" pos="0 0 0" size="0.01" group="1" rgba="1 0 0 -1"/>
                          <body name="gripper0_eef" pos="0 0 0.097" gravcomp="0">
                            <site name="gripper0_grip_site" pos="0 0 0" size="0.01" group="1" rgba="1 0 0 -0.5"/>
                            <site name="gripper0_ee_x" pos="0.1 0 0" quat="0.707105 0 0.707108 0" size="0.005 0.1" group="1" type="cylinder" rgba="1 0 0 0"/>
                            <site name="gripper0_ee_y" pos="0 0.1 0" quat="0.707105 0.707108 0 0" size="0.005 0.1" group="1" type="cylinder" rgba="0 1 0 0"/>
                            <site name="gripper0_ee_z" pos="0 0 0.1" size="0.005 0.1" group="1" type="cylinder" rgba="0 0 1 0"/>
                            <site name="gripper0_grip_site_cylinder" pos="0 0 0" size="0.005 10" group="1" type="cylinder" rgba="0 1 0 -0.3"/>
                          </body>
                          <body name="gripper0_leftfinger" pos="0 0 0.0524" quat="0.707107 0 0 0.707107" gravcomp="0">
                            <inertial pos="0 0 0.05" mass="0.1" diaginertia="0.01 0.01 0.005"/>
                            <joint name="gripper0_finger_joint1" pos="0 0 0" axis="0 1 0" type="slide" range="0 0.04" armature="1" damping="100" frictionloss="1"/>
                            <geom name="gripper0_finger1_visual" type="mesh" contype="0" conaffinity="0" group="1" rgba="0.499 0.499 0.499 1" mesh="gripper0_finger_vis"/>
                            <geom name="gripper0_finger1_collision" type="mesh" contype="0" condim="4" rgba="0 0 0.5 1" mesh="gripper0_finger"/>
                            <body name="gripper0_finger_joint1_tip" pos="0 0.0085 0.056" gravcomp="0">
                              <inertial pos="0 0 0" quat="0 0 0 1" mass="0.01" diaginertia="0.01 0.01 0.01"/>
                              <geom name="gripper0_finger1_pad_collision" size="0.008 0.004 0.008" pos="0 -0.005 -0.015" quat="0 0 0 1" type="box" friction="2 0.05 0.0001" solref="0.01 0.5" rgba="0 0 0.5 1"/>
                            </body>
                          </body>
                          <body name="gripper0_rightfinger" pos="0 0 0.0524" quat="0.707107 0 0 0.707107" gravcomp="0">
                            <inertial pos="0 0 0.05" mass="0.1" diaginertia="0.01 0.01 0.005"/>
                            <joint name="gripper0_finger_joint2" pos="0 0 0" axis="0 1 0" type="slide" range="-0.04 0" armature="1" damping="100" frictionloss="1"/>
                            <geom name="gripper0_finger2_visual" quat="0 0 0 1" type="mesh" contype="0" conaffinity="0" group="1" rgba="0.499 0.499 0.499 1" mesh="gripper0_finger_vis"/>
                            <geom name="gripper0_finger2_collision" quat="0 0 0 1" type="mesh" contype="0" condim="4" rgba="0 0 0.5 1" mesh="gripper0_finger"/>
                            <body name="gripper0_finger_joint2_tip" pos="0 -0.0085 0.056" gravcomp="0">
                              <inertial pos="0 0 0" quat="0 0 0 1" mass="0.01" diaginertia="0.01 0.01 0.01"/>
                              <geom name="gripper0_finger2_pad_collision" size="0.008 0.004 0.008" pos="0 0.005 -0.015" quat="0 0 0 1" type="box" friction="2 0.05 0.0001" solref="0.01 0.5" rgba="0 0 0.5 1"/>
                            </body>
                          </body>
                        </body>
                      </body>
                    </body>
                  </body>
                </body>
              </body>
            </body>
          </body>
        </body>
      </body>
      <body name="mount0_base" pos="0 0 0.01" gravcomp="0">
        <body name="mount0_controller_box" pos="0 0 0" gravcomp="0">
          <inertial pos="-0.325 0 -0.38" mass="46.64" diaginertia="1.71363 1.27988 0.809981"/>
          <geom name="mount0_controller_box_col" size="0.11 0.2 0.265" pos="-0.325 0 -0.38" type="box" rgba="0.5 0.5 0 1"/>
        </body>
        <body name="mount0_pedestal_feet" pos="0 0 0" gravcomp="0">
          <inertial pos="-0.1225 0 -0.758" mass="167.09" diaginertia="8.16095 9.59375 15.0785"/>
          <geom name="mount0_pedestal_feet_col" size="0.385 0.35 0.155" pos="-0.1225 0 -0.758" type="box" rgba="0.5 0.5 0 1"/>
        </body>
        <body name="mount0_torso" pos="0 0 0" gravcomp="0">
          <inertial pos="0 0 0" mass="0.0001" diaginertia="1e-08 1e-08 1e-08"/>
          <geom name="mount0_torso_vis" size="0.05 0.05 0.05" pos="0 0 -0.05" type="box" contype="0" conaffinity="0" group="1" rgba="0.2 0.2 0.2 1"/>
        </body>
        <body name="mount0_pedestal" pos="0 0 0" gravcomp="0">
          <inertial pos="0 0 0" quat="0.659267 -0.259505 -0.260945 0.655692" mass="60.864" diaginertia="6.0869 5.81635 4.20915"/>
          <geom name="mount0_pedestal_vis" type="mesh" contype="0" conaffinity="0" group="1" rgba="0.2 0.2 0.2 1" mesh="mount0_pedestal"/>
          <geom name="mount0_pedestal_col" size="0.18 0.31" pos="-0.02 0 -0.29" type="cylinder" rgba="0.5 0.5 0 1"/>
        </body>
      </body>
    </body>
    <body name="stand_root" pos="0 0 0" gravcomp="0">
      <joint name="stand_joint0" type="free"/>
      <geom name="stand_base" size="0.06 0.07 0.005" pos="0 0 -0.075" type="box" solimp="0.998 0.998 0.001 0.5 2" density="50000" rgba="0.5 0 0 1"/>
      <geom name="stand_base_vis" size="0.06 0.07 0.005" pos="0 0 -0.075" type="box" contype="0" conaffinity="0" group="1" mass="0" material="stand_brass_mat"/>
      <geom name="stand_wall0" size="0.0005 0.006 0.075" pos="0 0.0395 0.005" quat="0.707107 0 0 0.707107" type="box" solimp="0.998 0.998 0.001 0.5 2" density="50000" rgba="0.5 0 0 1"/>
      <geom name="stand_wall0_vis" size="0.0005 0.006 0.075" pos="0 0.0395 0.005" quat="0.707107 0 0 0.707107" type="box" contype="0" conaffinity="0" group="1" mass="0" material="stand_brass_mat"/>
      <geom name="stand_wall1" size="0.0005 0.006 0.075" pos="-0.0055 0.045 0.005" type="box" solimp="0.998 0.998 0.001 0.5 2" density="50000" rgba="0.5 0 0 1"/>
      <geom name="stand_wall1_vis" size="0.0005 0.006 0.075" pos="-0.0055 0.045 0.005" type="box" contype="0" conaffinity="0" group="1" mass="0" material="stand_brass_mat"/>
      <geom name="stand_wall2" size="0.0005 0.006 0.075" pos="0 0.0505 0.005" quat="0.707107 0 0 -0.707107" type="box" solimp="0.998 0.998 0.001 0.5 2" density="50000" rgba="0.5 0 0 1"/>
      <geom name="stand_wall2_vis" size="0.0005 0.006 0.075" pos="0 0.0505 0.005" quat="0.707107 0 0 -0.707107" type="box" contype="0" conaffinity="0" group="1" mass="0" material="stand_brass_mat"/>
      <geom name="stand_wall3" size="0.0005 0.006 0.075" pos="0.0055 0.045 0.005" quat="0 0 0 1" type="box" solimp="0.998 0.998 0.001 0.5 2" density="50000" rgba="0.5 0 0 1"/>
      <geom name="stand_wall3_vis" size="0.0005 0.006 0.075" pos="0.0055 0.045 0.005" quat="0 0 0 1" type="box" contype="0" conaffinity="0" group="1" mass="0" material="stand_brass_mat"/>
      <geom name="stand_hole_vis_vis" size="0.00385 0.00385 0.0005" pos="0 0.045 0.0795" type="box" contype="0" conaffinity="0" group="1" mass="0" rgba="0 1 0 0.5"/>
      <site name="stand_mount_site" pos="0 0 0.08" size="0.002" rgba="1 0 0 -1"/>
      <site name="stand_default_site" pos="0 0 0" size="0.002" rgba="1 0 0 0"/>
    </body>
    <body name="frame_root" pos="0 0 0" gravcomp="0">
      <joint name="frame_joint0" type="free"/>
      <geom name="frame_vertical_frame" size="0.00375 0.00375 0.08625" pos="0.04375 0 -0.00375" type="box" solimp="0.998 0.998 0.001 0.5 2" density="500" rgba="0.5 0 0 1"/>
      <geom name="frame_vertical_frame_vis" size="0.00375 0.00375 0.08625" pos="0.04375 0 -0.00375" type="box" contype="0" conaffinity="0" group="1" mass="0" material="frame_brass_mat"/>
      <geom name="frame_horizontal_frame" size="0.0475 0.00375 0.00375" pos="0 0 0.08625" type="box" solimp="0.998 0.998 0.001 0.5 2" density="500" rgba="0.5 0 0 1"/>
      <geom name="frame_horizontal_frame_vis" size="0.0475 0.00375 0.00375" pos="0 0 0.08625" type="box" contype="0" conaffinity="0" group="1" mass="0" material="frame_brass_mat"/>
      <geom name="frame_hook_frame" size="0.00375 0.00375 0.006" pos="-0.04375 0 0.096" type="box" solimp="0.998 0.998 0.001 0.5 2" density="500" rgba="0.5 0 0 1"/>
      <geom name="frame_hook_frame_vis" size="0.00375 0.00375 0.006" pos="-0.04375 0 0.096" type="box" contype="0" conaffinity="0" group="1" mass="0" material="frame_brass_mat"/>
      <geom name="frame_grip_frame" size="0.0127 0.0127 0.03175" pos="0.04375 0 0.0525" type="box" solimp="0.998 0.998 0.001 0.5 2" density="500" rgba="0.5 0 0 1"/>
      <geom name="frame_grip_frame_vis" size="0.0127 0.0127 0.03175" pos="0.04375 0 0.0525" type="box" contype="0" conaffinity="0" group="1" mass="0" material="frame_ceramic_mat" rgba="0.13 0.13 0.13 1"/>
      <geom name="frame_tip_cylinder" size="0.00325 0.0127" pos="0.04375 0 -0.1027" type="cylinder" solimp="0.998 0.998 0.001 0.5 2" density="500" rgba="0.5 0 0 1"/>
      <geom name="frame_tip_cylinder_vis" size="0.00325 0.0127" pos="0.04375 0 -0.1027" type="cylinder" contype="0" conaffinity="0" group="1" mass="0" material="frame_steel_mat"/>
      <geom name="frame_tip_cone_0" size="0.001 0.001 0.000186765" pos="0.04375 0 -0.134263" type="box" solimp="0.998 0.998 0.001 0.5 2" density="500" rgba="0.5 0 0 1"/>
      <geom name="frame_tip_cone_0_vis" size="0.001 0.001 0.000186765" pos="0.04375 0 -0.134263" type="box" contype="0" conaffinity="0" group="1" mass="0" material="frame_steel_mat"/>
      <geom name="frame_tip_cone_1" size="0.001045 0.001045 0.000186765" pos="0.04375 0 -0.13389" type="box" solimp="0.998 0.998 0.001 0.5 2" density="500" rgba="0.5 0 0 1"/>
      <geom name="frame_tip_cone_1_vis" size="0.001045 0.001045 0.000186765" pos="0.04375 0 -0.13389" type="box" contype="0" conaffinity="0" group="1" mass="0" material="frame_steel_mat"/>
      <geom name="frame_tip_cone_2" size="0.00109 0.00109 0.000186765" pos="0.04375 0 -0.133516" type="box" solimp="0.998 0.998 0.001 0.5 2" density="500" rgba="0.5 0 0 1"/>
      <geom name="frame_tip_cone_2_vis" size="0.00109 0.00109 0.000186765" pos="0.04375 0 -0.133516" type="box" contype="0" conaffinity="0" group="1" mass="0" material="frame_steel_mat"/>
      <geom name="frame_tip_cone_3" size="0.001135 0.001135 0.000186765" pos="0.04375 0 -0.133143" type="box" solimp="0.998 0.998 0.001 0.5 2" density="500" rgba="0.5 0 0 1"/>
      <geom name="frame_tip_cone_3_vis" size="0.001135 0.001135 0.000186765" pos="0.04375 0 -0.133143" type="box" contype="0" conaffinity="0" group="1" mass="0" material="frame_steel_mat"/>
      <geom name="frame_tip_cone_4" size="0.00118 0.00118 0.000186765" pos="0.04375 0 -0.132769" type="box" solimp="0.998 0.998 0.001 0.5 2" density="500" rgba="0.5 0 0 1"/>
      <geom name="frame_tip_cone_4_vis" size="0.00118 0.00118 0.000186765" pos="0.04375 0 -0.132769" type="box" contype="0" conaffinity="0" group="1" mass="0" material="frame_steel_mat"/>
      <geom name="frame_tip_cone_5" size="0.001225 0.001225 0.000186765" pos="0.04375 0 -0.132396" type="box" solimp="0.998 0.998 0.001 0.5 2" density="500" rgba="0.5 0 0 1"/>
      <geom name="frame_tip_cone_5_vis" size="0.001225 0.001225 0.000186765" pos="0.04375 0 -0.132396" type="box" contype="0" conaffinity="0" group="1" mass="0" material="frame_steel_mat"/>
      <geom name="frame_tip_cone_6" size="0.00127 0.00127 0.000186765" pos="0.04375 0 -0.132022" type="box" solimp="0.998 0.998 0.001 0.5 2" density="500" rgba="0.5 0 0 1"/>
      <geom name="frame_tip_cone_6_vis" size="0.00127 0.00127 0.000186765" pos="0.04375 0 -0.132022" type="box" contype="0" conaffinity="0" group="1" mass="0" material="frame_steel_mat"/>
      <geom name="frame_tip_cone_7" size="0.001315 0.001315 0.000186765" pos="0.04375 0 -0.131649" type="box" solimp="0.998 0.998 0.001 0.5 2" density="500" rgba="0.5 0 0 1"/>
      <geom name="frame_tip_cone_7_vis" size="0.001315 0.001315 0.000186765" pos="0.04375 0 -0.131649" type="box" contype="0" conaffinity="0" group="1" mass="0" material="frame_steel_mat"/>
      <geom name="frame_tip_cone_8" size="0.00136 0.00136 0.000186765" pos="0.04375 0 -0.131275" type="box" solimp="0.998 0.998 0.001 0.5 2" density="500" rgba="0.5 0 0 1"/>
      <geom name="frame_tip_cone_8_vis" size="0.00136 0.00136 0.000186765" pos="0.04375 0 -0.131275" type="box" contype="0" conaffinity="0" group="1" mass="0" material="frame_steel_mat"/>
      <geom name="frame_tip_cone_9" size="0.001405 0.001405 0.000186765" pos="0.04375 0 -0.130901" type="box" solimp="0.998 0.998 0.001 0.5 2" density="500" rgba="0.5 0 0 1"/>
      <geom name="frame_tip_cone_9_vis" size="0.001405 0.001405 0.000186765" pos="0.04375 0 -0.130901" type="box" contype="0" conaffinity="0" group="1" mass="0" material="frame_steel_mat"/>
      <geom name="frame_tip_cone_10" size="0.00145 0.00145 0.000186765" pos="0.04375 0 -0.130528" type="box" solimp="0.998 0.998 0.001 0.5 2" density="500" rgba="0.5 0 0 1"/>
      <geom name="frame_tip_cone_10_vis" size="0.00145 0.00145 0.000186765" pos="0.04375 0 -0.130528" type="box" contype="0" conaffinity="0" group="1" mass="0" material="frame_steel_mat"/>
      <geom name="frame_tip_cone_11" size="0.001495 0.001495 0.000186765" pos="0.04375 0 -0.130154" type="box" solimp="0.998 0.998 0.001 0.5 2" density="500" rgba="0.5 0 0 1"/>
      <geom name="frame_tip_cone_11_vis" size="0.001495 0.001495 0.000186765" pos="0.04375 0 -0.130154" type="box" contype="0" conaffinity="0" group="1" mass="0" material="frame_steel_mat"/>
      <geom name="frame_tip_cone_12" size="0.00154 0.00154 0.000186765" pos="0.04375 0 -0.129781" type="box" solimp="0.998 0.998 0.001 0.5 2" density="500" rgba="0.5 0 0 1"/>
      <geom name="frame_tip_cone_12_vis" size="0.00154 0.00154 0.000186765" pos="0.04375 0 -0.129781" type="box" contype="0" conaffinity="0" group="1" mass="0" material="frame_steel_mat"/>
      <geom name="frame_tip_cone_13" size="0.001585 0.001585 0.000186765" pos="0.04375 0 -0.129407" type="box" solimp="0.998 0.998 0.001 0.5 2" density="500" rgba="0.5 0 0 1"/>
      <geom name="frame_tip_cone_13_vis" size="0.001585 0.001585 0.000186765" pos="0.04375 0 -0.129407" type="box" contype="0" conaffinity="0" group="1" mass="0" material="frame_steel_mat"/>
      <geom name="frame_tip_cone_14" size="0.00163 0.00163 0.000186765" pos="0.04375 0 -0.129034" type="box" solimp="0.998 0.998 0.001 0.5 2" density="500" rgba="0.5 0 0 1"/>
      <geom name="frame_tip_cone_14_vis" size="0.00163 0.00163 0.000186765" pos="0.04375 0 -0.129034" type="box" contype="0" conaffinity="0" group="1" mass="0" material="frame_steel_mat"/>
      <geom name="frame_tip_cone_15" size="0.001675 0.001675 0.000186765" pos="0.04375 0 -0.12866" type="box" solimp="0.998 0.998 0.001 0.5 2" density="500" rgba="0.5 0 0 1"/>
      <geom name="frame_tip_cone_15_vis" size="0.001675 0.001675 0.000186765" pos="0.04375 0 -0.12866" type="box" contype="0" conaffinity="0" group="1" mass="0" material="frame_steel_mat"/>
      <geom name="frame_tip_cone_16" size="0.00172 0.00172 0.000186765" pos="0.04375 0 -0.128287" type="box" solimp="0.998 0.998 0.001 0.5 2" density="500" rgba="0.5 0 0 1"/>
      <geom name="frame_tip_cone_16_vis" size="0.00172 0.00172 0.000186765" pos="0.04375 0 -0.128287" type="box" contype="0" conaffinity="0" group="1" mass="0" material="frame_steel_mat"/>
      <geom name="frame_tip_cone_17" size="0.001765 0.001765 0.000186765" pos="0.04375 0 -0.127913" type="box" solimp="0.998 0.998 0.001 0.5 2" density="500" rgba="0.5 0 0 1"/>
      <geom name="frame_tip_cone_17_vis" size="0.001765 0.001765 0.000186765" pos="0.04375 0 -0.127913" type="box" contype="0" conaffinity="0" group="1" mass="0" material="frame_steel_mat"/>
      <geom name="frame_tip_cone_18" size="0.00181 0.00181 0.000186765" pos="0.04375 0 -0.12754" type="box" solimp="0.998 0.998 0.001 0.5 2" density="500" rgba="0.5 0 0 1"/>
      <geom name="frame_tip_cone_18_vis" size="0.00181 0.00181 0.000186765" pos="0.04375 0 -0.12754" type="box" contype="0" conaffinity="0" group="1" mass="0" material="frame_steel_mat"/>
      <geom name="frame_tip_cone_19" size="0.001855 0.001855 0.000186765" pos="0.04375 0 -0.127166" type="box" solimp="0.998 0.998 0.001 0.5 2" density="500" rgba="0.5 0 0 1"/>
      <geom name="frame_tip_cone_19_vis" size="0.001855 0.001855 0.000186765" pos="0.04375 0 -0.127166" type="box" contype="0" conaffinity="0" group="1" mass="0" material="frame_steel_mat"/>
      <geom name="frame_tip_cone_20" size="0.0019 0.0019 0.000186765" pos="0.04375 0 -0.126793" type="box" solimp="0.998 0.998 0.001 0.5 2" density="500" rgba="0.5 0 0 1"/>
      <geom name="frame_tip_cone_20_vis" size="0.0019 0.0019 0.000186765" pos="0.04375 0 -0.126793" type="box" contype="0" conaffinity="0" group="1" mass="0" material="frame_steel_mat"/>
      <geom name="frame_tip_cone_21" size="0.001945 0.001945 0.000186765" pos="0.04375 0 -0.126419" type="box" solimp="0.998 0.998 0.001 0.5 2" density="500" rgba="0.5 0 0 1"/>
      <geom name="frame_tip_cone_21_vis" size="0.001945 0.001945 0.000186765" pos="0.04375 0 -0.126419" type="box" contype="0" conaffinity="0" group="1" mass="0" material="frame_steel_mat"/>
      <geom name="frame_tip_cone_22" size="0.00199 0.00199 0.000186765" pos="0.04375 0 -0.126046" type="box" solimp="0.998 0.998 0.001 0.5 2" density="500" rgba="0.5 0 0 1"/>
      <geom name="frame_tip_cone_22_vis" size="0.00199 0.00199 0.000186765" pos="0.04375 0 -0.126046" type="box" contype="0" conaffinity="0" group="1" mass="0" material="frame_steel_mat"/>
      <geom name="frame_tip_cone_23" size="0.002035 0.002035 0.000186765" pos="0.04375 0 -0.125672" type="box" solimp="0.998 0.998 0.001 0.5 2" density="500" rgba="0.5 0 0 1"/>
      <geom name="frame_tip_cone_23_vis" size="0.002035 0.002035 0.000186765" pos="0.04375 0 -0.125672" type="box" contype="0" conaffinity="0" group="1" mass="0" material="frame_steel_mat"/>
      <geom name="frame_tip_cone_24" size="0.00208 0.00208 0.000186765" pos="0.04375 0 -0.125299" type="box" solimp="0.998 0.998 0.001 0.5 2" density="500" rgba="0.5 0 0 1"/>
      <geom name="frame_tip_cone_24_vis" size="0.00208 0.00208 0.000186765" pos="0.04375 0 -0.125299" type="box" contype="0" conaffinity="0" group="1" mass="0" material="frame_steel_mat"/>
      <geom name="frame_tip_cone_25" size="0.002125 0.002125 0.000186765" pos="0.04375 0 -0.124925" type="box" solimp="0.998 0.998 0.001 0.5 2" density="500" rgba="0.5 0 0 1"/>
      <geom name="frame_tip_cone_25_vis" size="0.002125 0.002125 0.000186765" pos="0.04375 0 -0.124925" type="box" contype="0" conaffinity="0" group="1" mass="0" material="frame_steel_mat"/>
      <geom name="frame_tip_cone_26" size="0.00217 0.00217 0.000186765" pos="0.04375 0 -0.124551" type="box" solimp="0.998 0.998 0.001 0.5 2" density="500" rgba="0.5 0 0 1"/>
      <geom name="frame_tip_cone_26_vis" size="0.00217 0.00217 0.000186765" pos="0.04375 0 -0.124551" type="box" contype="0" conaffinity="0" group="1" mass="0" material="frame_steel_mat"/>
      <geom name="frame_tip_cone_27" size="0.002215 0.002215 0.000186765" pos="0.04375 0 -0.124178" type="box" solimp="0.998 0.998 0.001 0.5 2" density="500" rgba="0.5 0 0 1"/>
      <geom name="frame_tip_cone_27_vis" size="0.002215 0.002215 0.000186765" pos="0.04375 0 -0.124178" type="box" contype="0" conaffinity="0" group="1" mass="0" material="frame_steel_mat"/>
      <geom name="frame_tip_cone_28" size="0.00226 0.00226 0.000186765" pos="0.04375 0 -0.123804" type="box" solimp="0.998 0.998 0.001 0.5 2" density="500" rgba="0.5 0 0 1"/>
      <geom name="frame_tip_cone_28_vis" size="0.00226 0.00226 0.000186765" pos="0.04375 0 -0.123804" type="box" contype="0" conaffinity="0" group="1" mass="0" material="frame_steel_mat"/>
      <geom name="frame_tip_cone_29" size="0.002305 0.002305 0.000186765" pos="0.04375 0 -0.123431" type="box" solimp="0.998 0.998 0.001 0.5 2" density="500" rgba="0.5 0 0 1"/>
      <geom name="frame_tip_cone_29_vis" size="0.002305 0.002305 0.000186765" pos="0.04375 0 -0.123431" type="box" contype="0" conaffinity="0" group="1" mass="0" material="frame_steel_mat"/>
      <geom name="frame_tip_cone_30" size="0.00235 0.00235 0.000186765" pos="0.04375 0 -0.123057" type="box" solimp="0.998 0.998 0.001 0.5 2" density="500" rgba="0.5 0 0 1"/>
      <geom name="frame_tip_cone_30_vis" size="0.00235 0.00235 0.000186765" pos="0.04375 0 -0.123057" type="box" contype="0" conaffinity="0" group="1" mass="0" material="frame_steel_mat"/>
      <geom name="frame_tip_cone_31" size="0.002395 0.002395 0.000186765" pos="0.04375 0 -0.122684" type="box" solimp="0.998 0.998 0.001 0.5 2" density="500" rgba="0.5 0 0 1"/>
      <geom name="frame_tip_cone_31_vis" size="0.002395 0.002395 0.000186765" pos="0.04375 0 -0.122684" type="box" contype="0" conaffinity="0" group="1" mass="0" material="frame_steel_mat"/>
      <geom name="frame_tip_cone_32" size="0.00244 0.00244 0.000186765" pos="0.04375 0 -0.12231" type="box" solimp="0.998 0.998 0.001 0.5 2" density="500" rgba="0.5 0 0 1"/>
      <geom name="frame_tip_cone_32_vis" size="0.00244 0.00244 0.000186765" pos="0.04375 0 -0.12231" type="box" contype="0" conaffinity="0" group="1" mass="0" material="frame_steel_mat"/>
      <geom name="frame_tip_cone_33" size="0.002485 0.002485 0.000186765" pos="0.04375 0 -0.121937" type="box" solimp="0.998 0.998 0.001 0.5 2" density="500" rgba="0.5 0 0 1"/>
      <geom name="frame_tip_cone_33_vis" size="0.002485 0.002485 0.000186765" pos="0.04375 0 -0.121937" type="box" contype="0" conaffinity="0" group="1" mass="0" material="frame_steel_mat"/>
      <geom name="frame_tip_cone_34" size="0.00253 0.00253 0.000186765" pos="0.04375 0 -0.121563" type="box" solimp="0.998 0.998 0.001 0.5 2" density="500" rgba="0.5 0 0 1"/>
      <geom name="frame_tip_cone_34_vis" size="0.00253 0.00253 0.000186765" pos="0.04375 0 -0.121563" type="box" contype="0" conaffinity="0" group="1" mass="0" material="frame_steel_mat"/>
      <geom name="frame_tip_cone_35" size="0.002575 0.002575 0.000186765" pos="0.04375 0 -0.12119" type="box" solimp="0.998 0.998 0.001 0.5 2" density="500" rgba="0.5 0 0 1"/>
      <geom name="frame_tip_cone_35_vis" size="0.002575 0.002575 0.000186765" pos="0.04375 0 -0.12119" type="box" contype="0" conaffinity="0" group="1" mass="0" material="frame_steel_mat"/>
      <geom name="frame_tip_cone_36" size="0.00262 0.00262 0.000186765" pos="0.04375 0 -0.120816" type="box" solimp="0.998 0.998 0.001 0.5 2" density="500" rgba="0.5 0 0 1"/>
      <geom name="frame_tip_cone_36_vis" size="0.00262 0.00262 0.000186765" pos="0.04375 0 -0.120816" type="box" contype="0" conaffinity="0" group="1" mass="0" material="frame_steel_mat"/>
      <geom name="frame_tip_cone_37" size="0.002665 0.002665 0.000186765" pos="0.04375 0 -0.120443" type="box" solimp="0.998 0.998 0.001 0.5 2" density="500" rgba="0.5 0 0 1"/>
      <geom name="frame_tip_cone_37_vis" size="0.002665 0.002665 0.000186765" pos="0.04375 0 -0.120443" type="box" contype="0" conaffinity="0" group="1" mass="0" material="frame_steel_mat"/>
      <geom name="frame_tip_cone_38" size="0.00271 0.00271 0.000186765" pos="0.04375 0 -0.120069" type="box" solimp="0.998 0.998 0.001 0.5 2" density="500" rgba="0.5 0 0 1"/>
      <geom name="frame_tip_cone_38_vis" size="0.00271 0.00271 0.000186765" pos="0.04375 0 -0.120069" type="box" contype="0" conaffinity="0" group="1" mass="0" material="frame_steel_mat"/>
      <geom name="frame_tip_cone_39" size="0.002755 0.002755 0.000186765" pos="0.04375 0 -0.119696" type="box" solimp="0.998 0.998 0.001 0.5 2" density="500" rgba="0.5 0 0 1"/>
      <geom name="frame_tip_cone_39_vis" size="0.002755 0.002755 0.000186765" pos="0.04375 0 -0.119696" type="box" contype="0" conaffinity="0" group="1" mass="0" material="frame_steel_mat"/>
      <geom name="frame_tip_cone_40" size="0.0028 0.0028 0.000186765" pos="0.04375 0 -0.119322" type="box" solimp="0.998 0.998 0.001 0.5 2" density="500" rgba="0.5 0 0 1"/>
      <geom name="frame_tip_cone_40_vis" size="0.0028 0.0028 0.000186765" pos="0.04375 0 -0.119322" type="box" contype="0" conaffinity="0" group="1" mass="0" material="frame_steel_mat"/>
      <geom name="frame_tip_cone_41" size="0.002845 0.002845 0.000186765" pos="0.04375 0 -0.118949" type="box" solimp="0.998 0.998 0.001 0.5 2" density="500" rgba="0.5 0 0 1"/>
      <geom name="frame_tip_cone_41_vis" size="0.002845 0.002845 0.000186765" pos="0.04375 0 -0.118949" type="box" contype="0" conaffinity="0" group="1" mass="0" material="frame_steel_mat"/>
      <geom name="frame_tip_cone_42" size="0.00289 0.00289 0.000186765" pos="0.04375 0 -0.118575" type="box" solimp="0.998 0.998 0.001 0.5 2" density="500" rgba="0.5 0 0 1"/>
      <geom name="frame_tip_cone_42_vis" size="0.00289 0.00289 0.000186765" pos="0.04375 0 -0.118575" type="box" contype="0" conaffinity="0" group="1" mass="0" material="frame_steel_mat"/>
      <geom name="frame_tip_cone_43" size="0.002935 0.002935 0.000186765" pos="0.04375 0 -0.118201" type="box" solimp="0.998 0.998 0.001 0.5 2" density="500" rgba="0.5 0 0 1"/>
      <geom name="frame_tip_cone_43_vis" size="0.002935 0.002935 0.000186765" pos="0.04375 0 -0.118201" type="box" contype="0" conaffinity="0" group="1" mass="0" material="frame_steel_mat"/>
      <geom name="frame_tip_cone_44" size="0.00298 0.00298 0.000186765" pos="0.04375 0 -0.117828" type="box" solimp="0.998 0.998 0.001 0.5 2" density="500" rgba="0.5 0 0 1"/>
      <geom name="frame_tip_cone_44_vis" size="0.00298 0.00298 0.000186765" pos="0.04375 0 -0.117828" type="box" contype="0" conaffinity="0" group="1" mass="0" material="frame_steel_mat"/>
      <geom name="frame_tip_cone_45" size="0.003025 0.003025 0.000186765" pos="0.04375 0 -0.117454" type="box" solimp="0.998 0.998 0.001 0.5 2" density="500" rgba="0.5 0 0 1"/>
      <geom name="frame_tip_cone_45_vis" size="0.003025 0.003025 0.000186765" pos="0.04375 0 -0.117454" type="box" contype="0" conaffinity="0" group="1" mass="0" material="frame_steel_mat"/>
      <geom name="frame_tip_cone_46" size="0.00307 0.00307 0.000186765" pos="0.04375 0 -0.117081" type="box" solimp="0.998 0.998 0.001 0.5 2" density="500" rgba="0.5 0 0 1"/>
      <geom name="frame_tip_cone_46_vis" size="0.00307 0.00307 0.000186765" pos="0.04375 0 -0.117081" type="box" contype="0" conaffinity="0" group="1" mass="0" material="frame_steel_mat"/>
      <geom name="frame_tip_cone_47" size="0.003115 0.003115 0.000186765" pos="0.04375 0 -0.116707" type="box" solimp="0.998 0.998 0.001 0.5 2" density="500" rgba="0.5 0 0 1"/>
      <geom name="frame_tip_cone_47_vis" size="0.003115 0.003115 0.000186765" pos="0.04375 0 -0.116707" type="box" contype="0" conaffinity="0" group="1" mass="0" material="frame_steel_mat"/>
      <geom name="frame_tip_cone_48" size="0.00316 0.00316 0.000186765" pos="0.04375 0 -0.116334" type="box" solimp="0.998 0.998 0.001 0.5 2" density="500" rgba="0.5 0 0 1"/>
      <geom name="frame_tip_cone_48_vis" size="0.00316 0.00316 0.000186765" pos="0.04375 0 -0.116334" type="box" contype="0" conaffinity="0" group="1" mass="0" material="frame_steel_mat"/>
      <geom name="frame_tip_cone_49" size="0.003205 0.003205 0.000186765" pos="0.04375 0 -0.11596" type="box" solimp="0.998 0.998 0.001 0.5 2" density="500" rgba="0.5 0 0 1"/>
      <geom name="frame_tip_cone_49_vis" size="0.003205 0.003205 0.000186765" pos="0.04375 0 -0.11596" type="box" contype="0" conaffinity="0" group="1" mass="0" material="frame_steel_mat"/>
      <geom name="frame_tip_cone_50" size="0.00325 0.00325 0.000186765" pos="0.04375 0 -0.115587" type="box" solimp="0.998 0.998 0.001 0.5 2" density="500" rgba="0.5 0 0 1"/>
      <geom name="frame_tip_cone_50_vis" size="0.00325 0.00325 0.000186765" pos="0.04375 0 -0.115587" type="box" contype="0" conaffinity="0" group="1" mass="0" material="frame_steel_mat"/>
      <site name="frame_hang_site" pos="-0.0475 0 0.08625" size="0.002" rgba="1 0 0 -1"/>
      <site name="frame_mount_site" pos="0.04375 0 -0.09" size="0.002" rgba="0 1 0 -1"/>
      <site name="frame_intersection_site" pos="0.04375 0 0.08625" size="0.002" rgba="0 0 1 -1"/>
      <site name="frame_tip_site" pos="0.04375 0 -0.13445" size="0.002" rgba="1 0 0 -1"/>
      <site name="frame_default_site" pos="0 0 0" size="0.002" rgba="1 0 0 0"/>
    </body>
    <body name="tool_root" pos="0 0 0" gravcomp="0">
      <joint name="tool_joint0" type="free" damping="0.0005"/>
      <site name="tool_default_site" pos="0 0 0" size="0.002" rgba="1 0 0 0"/>
      <body name="tool_hole1_root" pos="-0.0935328 0 0" gravcomp="0">
        <geom name="tool_hole1_hc_0" size="0.00323358 0.00669696 0.0035" pos="-0.0129343 0 0" quat="0 0 0 1" type="box" condim="4" friction="0.95 0.3 0.1" solimp="0.998 0.998 0.001 0.5 2" density="2000" rgba="0.5 0 0 1"/>
        <geom name="tool_hole1_hc_0_vis" size="0.00323358 0.00669696 0.0035" pos="-0.0129343 0 0" quat="0 0 0 1" type="box" contype="0" conaffinity="0" group="1" mass="0" material="tool_hole1_steel_mat"/>
        <geom name="tool_hole1_hc_1" size="0.00323358 0.00669696 0.0035" pos="-0.00914594 0.00914594 0" quat="0.382683 0 0 0.92388" type="box" condim="4" friction="0.95 0.3 0.1" solimp="0.998 0.998 0.001 0.5 2" density="2000" rgba="0.5 0 0 1"/>
        <geom name="tool_hole1_hc_1_vis" size="0.00323358 0.00669696 0.0035" pos="-0.00914594 0.00914594 0" quat="0.382683 0 0 0.92388" type="box" contype="0" conaffinity="0" group="1" mass="0" material="tool_hole1_steel_mat"/>
        <geom name="tool_hole1_hc_2" size="0.00323358 0.00669696 0.0035" pos="0 0.0129343 0" quat="0.707107 0 0 0.707107" type="box" condim="4" friction="0.95 0.3 0.1" solimp="0.998 0.998 0.001 0.5 2" density="2000" rgba="0.5 0 0 1"/>
        <geom name="tool_hole1_hc_2_vis" size="0.00323358 0.00669696 0.0035" pos="0 0.0129343 0" quat="0.707107 0 0 0.707107" type="box" contype="0" conaffinity="0" group="1" mass="0" material="tool_hole1_steel_mat"/>
        <geom name="tool_hole1_hc_3" size="0.00323358 0.00669696 0.0035" pos="0.00914594 0.00914594 0" quat="0.92388 0 0 0.382683" type="box" condim="4" friction="0.95 0.3 0.1" solimp="0.998 0.998 0.001 0.5 2" density="2000" rgba="0.5 0 0 1"/>
        <geom name="tool_hole1_hc_3_vis" size="0.00323358 0.00669696 0.0035" pos="0.00914594 0.00914594 0" quat="0.92388 0 0 0.382683" type="box" contype="0" conaffinity="0" group="1" mass="0" material="tool_hole1_steel_mat"/>
        <geom name="tool_hole1_hc_4" size="0.00323358 0.00669696 0.0035" pos="0.0129343 0 0" type="box" condim="4" friction="0.95 0.3 0.1" solimp="0.998 0.998 0.001 0.5 2" density="2000" rgba="0.5 0 0 1"/>
        <geom name="tool_hole1_hc_4_vis" size="0.00323358 0.00669696 0.0035" pos="0.0129343 0 0" type="box" contype="0" conaffinity="0" group="1" mass="0" material="tool_hole1_steel_mat"/>
        <geom name="tool_hole1_hc_5" size="0.00323358 0.00669696 0.0035" pos="0.00914594 -0.00914594 0" quat="0.92388 0 0 -0.382683" type="box" condim="4" friction="0.95 0.3 0.1" solimp="0.998 0.998 0.001 0.5 2" density="2000" rgba="0.5 0 0 1"/>
        <geom name="tool_hole1_hc_5_vis" size="0.00323358 0.00669696 0.0035" pos="0.00914594 -0.00914594 0" quat="0.92388 0 0 -0.382683" type="box" contype="0" conaffinity="0" group="1" mass="0" material="tool_hole1_steel_mat"/>
        <geom name="tool_hole1_hc_6" size="0.00323358 0.00669696 0.0035" pos="0 -0.0129343 0" quat="0.707107 0 0 -0.707107" type="box" condim="4" friction="0.95 0.3 0.1" solimp="0.998 0.998 0.001 0.5 2" density="2000" rgba="0.5 0 0 1"/>
        <geom name="tool_hole1_hc_6_vis" size="0.00323358 0.00669696 0.0035" pos="0 -0.0129343 0" quat="0.707107 0 0 -0.707107" type="box" contype="0" conaffinity="0" group="1" mass="0" material="tool_hole1_steel_mat"/>
        <geom name="tool_hole1_hc_7" size="0.00323358 0.00669696 0.0035" pos="-0.00914594 -0.00914594 0" quat="0.382683 0 0 -0.92388" type="box" condim="4" friction="0.95 0.3 0.1" solimp="0.998 0.998 0.001 0.5 2" density="2000" rgba="0.5 0 0 1"/>
        <geom name="tool_hole1_hc_7_vis" size="0.00323358 0.00669696 0.0035" pos="-0.00914594 -0.00914594 0" quat="0.382683 0 0 -0.92388" type="box" contype="0" conaffinity="0" group="1" mass="0" material="tool_hole1_steel_mat"/>
        <site name="tool_hole1_center" pos="0 0 0" size="0.002" rgba="1 0 0 -1"/>
        <site name="tool_hole1_default_site" pos="0 0 0" size="0.002" rgba="1 0 0 0"/>
      </body>
      <body name="tool_hole2_root" pos="0.0928806 0 0" gravcomp="0">
        <geom name="tool_hole2_hc_0" size="0.0023097 0.00574025 0.0035" pos="-0.0115485 0 0" quat="0 0 0 1" type="box" condim="4" friction="0.95 0.3 0.1" solimp="0.998 0.998 0.001 0.5 2" density="2000" rgba="0.5 0 0 1"/>
        <geom name="tool_hole2_hc_0_vis" size="0.0023097 0.00574025 0.0035" pos="-0.0115485 0 0" quat="0 0 0 1" type="box" contype="0" conaffinity="0" group="1" mass="0" material="tool_hole2_steel_mat"/>
        <geom name="tool_hole2_hc_1" size="0.0023097 0.00574025 0.0035" pos="-0.00816602 0.00816602 0" quat="0.382683 0 0 0.92388" type="box" condim="4" friction="0.95 0.3 0.1" solimp="0.998 0.998 0.001 0.5 2" density="2000" rgba="0.5 0 0 1"/>
        <geom name="tool_hole2_hc_1_vis" size="0.0023097 0.00574025 0.0035" pos="-0.00816602 0.00816602 0" quat="0.382683 0 0 0.92388" type="box" contype="0" conaffinity="0" group="1" mass="0" material="tool_hole2_steel_mat"/>
        <geom name="tool_hole2_hc_2" size="0.0023097 0.00574025 0.0035" pos="0 0.0115485 0" quat="0.707107 0 0 0.707107" type="box" condim="4" friction="0.95 0.3 0.1" solimp="0.998 0.998 0.001 0.5 2" density="2000" rgba="0.5 0 0 1"/>
        <geom name="tool_hole2_hc_2_vis" size="0.0023097 0.00574025 0.0035" pos="0 0.0115485 0" quat="0.707107 0 0 0.707107" type="box" contype="0" conaffinity="0" group="1" mass="0" material="tool_hole2_steel_mat"/>
        <geom name="tool_hole2_hc_3" size="0.0023097 0.00574025 0.0035" pos="0.00816602 0.00816602 0" quat="0.92388 0 0 0.382683" type="box" condim="4" friction="0.95 0.3 0.1" solimp="0.998 0.998 0.001 0.5 2" density="2000" rgba="0.5 0 0 1"/>
        <geom name="tool_hole2_hc_3_vis" size="0.0023097 0.00574025 0.0035" pos="0.00816602 0.00816602 0" quat="0.92388 0 0 0.382683" type="box" contype="0" conaffinity="0" group="1" mass="0" material="tool_hole2_steel_mat"/>
        <geom name="tool_hole2_hc_4" size="0.0023097 0.00574025 0.0035" pos="0.0115485 0 0" type="box" condim="4" friction="0.95 0.3 0.1" solimp="0.998 0.998 0.001 0.5 2" density="2000" rgba="0.5 0 0 1"/>
        <geom name="tool_hole2_hc_4_vis" size="0.0023097 0.00574025 0.0035" pos="0.0115485 0 0" type="box" contype="0" conaffinity="0" group="1" mass="0" material="tool_hole2_steel_mat"/>
        <geom name="tool_hole2_hc_5" size="0.0023097 0.00574025 0.0035" pos="0.00816602 -0.00816602 0" quat="0.92388 0 0 -0.382683" type="box" condim="4" friction="0.95 0.3 0.1" solimp="0.998 0.998 0.001 0.5 2" density="2000" rgba="0.5 0 0 1"/>
        <geom name="tool_hole2_hc_5_vis" size="0.0023097 0.00574025 0.0035" pos="0.00816602 -0.00816602 0" quat="0.92388 0 0 -0.382683" type="box" contype="0" conaffinity="0" group="1" mass="0" material="tool_hole2_steel_mat"/>
        <geom name="tool_hole2_hc_6" size="0.0023097 0.00574025 0.0035" pos="0 -0.0115485 0" quat="0.707107 0 0 -0.707107" type="box" condim="4" friction="0.95 0.3 0.1" solimp="0.998 0.998 0.001 0.5 2" density="2000" rgba="0.5 0 0 1"/>
        <geom name="tool_hole2_hc_6_vis" size="0.0023097 0.00574025 0.0035" pos="0 -0.0115485 0" quat="0.707107 0 0 -0.707107" type="box" contype="0" conaffinity="0" group="1" mass="0" material="tool_hole2_steel_mat"/>
        <geom name="tool_hole2_hc_7" size="0.0023097 0.00574025 0.0035" pos="-0.00816602 -0.00816602 0" quat="0.382683 0 0 -0.92388" type="box" condim="4" friction="0.95 0.3 0.1" solimp="0.998 0.998 0.001 0.5 2" density="2000" rgba="0.5 0 0 1"/>
        <geom name="tool_hole2_hc_7_vis" size="0.0023097 0.00574025 0.0035" pos="-0.00816602 -0.00816602 0" quat="0.382683 0 0 -0.92388" type="box" contype="0" conaffinity="0" group="1" mass="0" material="tool_hole2_steel_mat"/>
        <site name="tool_hole2_center" pos="0 0 0" size="0.002" rgba="1 0 0 -1"/>
        <site name="tool_hole2_default_site" pos="0 0 0" size="0.002" rgba="1 0 0 0"/>
      </body>
      <body name="tool_handle_main" pos="0 0 0" gravcomp="0">
        <geom name="tool_handle_g0" size="0.0825 0.00875 0.0016" type="box" friction="0.95 0.3 0.1" solimp="0.998 0.998 0.001 0.5 2" density="2000" rgba="0.5 0 0 1"/>
        <geom name="tool_handle_g0_vis" size="0.0825 0.00875 0.0016" type="box" contype="0" conaffinity="0" group="1" mass="0" material="tool_handle_steel_mat"/>
        <site name="tool_handle_default_site" pos="0 0 0" size="0.002" rgba="1 0 0 -1"/>
      </body>
      <body name="tool_grip_main" pos="0 0 0" quat="0.707107 0 0.707107 0" gravcomp="0">
        <geom name="tool_grip_g0" size="0.015 0.015 0.04" type="box" solimp="0.998 0.998 0.001 0.5 2" density="2000" rgba="0.5 0 0 1"/>
        <geom name="tool_grip_g0_vis" size="0.015 0.015 0.04" type="box" contype="0" conaffinity="0" group="1" mass="0" rgba="0.13 0.13 0.13 1"/>
        <site name="tool_grip_default_site" pos="0 0 0" size="0.002" rgba="1 0 0 -1"/>
      </body>
    </body>
  </worldbody>
  <actuator>
    <general name="robot0_torq_j1" joint="robot0_joint1" ctrlrange="-80 80" actdim="0"/>
    <general name="robot0_torq_j2" joint="robot0_joint2" ctrlrange="-80 80" actdim="0"/>
    <general name="robot0_torq_j3" joint="robot0_joint3" ctrlrange="-80 80" actdim="0"/>
    <general name="robot0_torq_j4" joint="robot0_joint4" ctrlrange="-80 80" actdim="0"/>
    <general name="robot0_torq_j5" joint="robot0_joint5" ctrlrange="-80 80" actdim="0"/>
    <general name="robot0_torq_j6" joint="robot0_joint6" ctrlrange="-12 12" actdim="0"/>
    <general name="robot0_torq_j7" joint="robot0_joint7" ctrlrange="-12 12" actdim="0"/>
    <general name="gripper0_gripper_finger_joint1" joint="gripper0_finger_joint1" ctrlrange="0 0.04" forcerange="-20 20" actdim="0" biastype="affine" gainprm="1000 0 0 0 0 0 0 0 0 0" biasprm="0 -1000 0 0 0 0 0 0 0 0"/>
    <general name="gripper0_gripper_finger_joint2" joint="gripper0_finger_joint2" ctrlrange="-0.04 0" forcerange="-20 20" actdim="0" biastype="affine" gainprm="1000 0 0 0 0 0 0 0 0 0" biasprm="0 -1000 0 0 0 0 0 0 0 0"/>
  </actuator>
  <sensor>
    <force site="gripper0_ft_frame" name="gripper0_force_ee"/>
    <torque site="gripper0_ft_frame" name="gripper0_torque_ee"/>
  </sensor>
</mujoco>